<?xml version="1.0" ?>
<sdf version="1.6">
  <world name="buoyancy">
    <model name="thruster">
      <pose>0 0 0 3.141592 0 0</pose>
      <link name='thruster_body'>
        <pose>0 0 0 0 0 0</pose>
        <inertial>
          <mass>0.5</mass>
          <inertia>
            <ixx>0.269653369</ixx>
            <ixy>0</ixy>
            <ixz>0</ixz>
            <iyy>0.269653369</iyy>
            <iyz>0</iyz>
            <izz>0.015707963</izz>
          </inertia>
        </inertial>

        <visual name='thruster_body_visual'>
          <geometry>
            <cylinder>
              <radius>0.01</radius>
              <length>0.05</length>
            </cylinder>
          </geometry>
        </visual>

        <collision name='thruster_body_collision'>
          <geometry>
            <cylinder>
              <radius>0.01</radius>
              <length>0.05</length>
            </cylinder>
          </geometry>
        </collision>
      </link>

      <link name='thruster_blade'>
        <pose>0 0 0 0 0 0</pose>
        <inertial>
          <mass>0.5</mass>
          <inertia>
            <ixx>0.1</ixx>
            <ixy>0</ixy>
            <ixz>0</ixz>
            <iyy>0.1</iyy>
            <iyz>0</iyz>
            <izz>0.2</izz>
          </inertia>
        </inertial>

        <visual name="blade1_visual">
          <pose>0.03 0.0 0 -0.7853981633974483 0 0.0</pose>
          <geometry>
            <box>
              <size>0.04 0.02 0.005</size>
            </box>
          </geometry>
        </visual>
        <collision name="blade1_collision">
          <pose>0.03 0.0 0 -0.7853981633974483 0 0.0</pose>
          <geometry>
            <box>
              <size>0.04 0.02 0.005</size>
            </box>
          </geometry>
        </collision>

        <visual name="blade2_visual">
          <pose>0.0 0.03 0 -0.7853981633974483 0 1.5707963267948966</pose>
          <geometry>
            <box>
              <size>0.04 0.02 0.005</size>
            </box>
          </geometry>
        </visual>
        <collision name="blade2_collision">
          <pose>0.0 0.03 0 -0.7853981633974483 0 1.5707963267948966</pose>
          <geometry>
            <box>
              <size>0.04 0.02 0.005</size>
            </box>
          </geometry>
        </collision>

        <visual name="blade3_visual">
          <pose>-0.03 -0.0 0 0.7853981633974483 0 0.0</pose>
          <geometry>
            <box>
              <size>0.04 0.02 0.005</size>
            </box>
          </geometry>
        </visual>
        <collision name="blade3_collision">
          <pose>-0.03 -0.0 0 0.7853981633974483 0 0.0</pose>
          <geometry>
            <box>
              <size>0.04 0.02 0.005</size>
            </box>
          </geometry>
        </collision>

        <visual name="blade4_visual">
          <pose>-0.0 -0.03 0 0.7853981633974483 0 1.5707963267948966</pose>
          <geometry>
            <box>
              <size>0.04 0.02 0.005</size>
            </box>
          </geometry>
        </visual>
        <collision name="blade4_collision">
          <pose>-0.0 -0.03 0 0.7853981633974483 0 1.5707963267948966</pose>
          <geometry>
            <box>
              <size>0.04 0.02 0.005</size>
            </box>
          </geometry>
        </collision>
      </link>

      <joint name='thruster_body_blade_joint' type='revolute'>
        <parent>thruster_body</parent>
        <child>thruster_blade</child>
        <axis>
          <xyz>0 0 1</xyz>
          <use_parent_model_frame>1</use_parent_model_frame>
          <limit>
            <lower>-1e+12</lower>
            <upper>1e+12</upper>
            <effort>-1</effort>
            <velocity>-1</velocity>
          </limit>
        </axis>
      </joint>

      <plugin
        filename="ignition-gazebo-lift-drag-system"
        name="ignition::gazebo::systems::LiftDrag">
        <air_density>1000</air_density>
        <cla>1.2535816618911175</cla>
        <cla_stall>-1.4326647564469914</cla_stall>
        <cda>0</cda>
        <cda_stall>1.4326647564469914</cda_stall>
        <alpha_stall>1.396</alpha_stall>
        <a0>0</a0>
        <area>0.27637</area>
        <upward>0 -0.707106781186547 -0.707106781186547</upward>
        <forward>0 -0.707106781186547 0.707106781186547</forward>
        <link_name>thruster_blade</link_name>
        <cp>0.35 0 0</cp>
      </plugin>

      <plugin
        filename="ignition-gazebo-lift-drag-system"
        name="ignition::gazebo::systems::LiftDrag">
        <air_density>1000</air_density>
        <cla>1.2535816618911175</cla>
        <cla_stall>-1.4326647564469914</cla_stall>
        <cda>0</cda>
        <cda_stall>1.4326647564469914</cda_stall>
        <alpha_stall>1.396</alpha_stall>
        <a0>0</a0>
        <area>0.27637</area>
        <upward>-0.707106781186547 0 -0.707106781186547</upward>
        <forward>-0.707106781186547 0 0.707106781186547</forward>
        <link_name>thruster_blade</link_name>
        <cp>0 -0.35 0</cp>
      </plugin>

      <plugin
        filename="ignition-gazebo-lift-drag-system"
        name="ignition::gazebo::systems::LiftDrag">

        <air_density>1000</air_density>
        <cla>1.2535816618911175</cla>
        <cla_stall>-1.4326647564469914</cla_stall>
        <cda>0</cda>
        <cda_stall>1.4326647564469914</cda_stall>
        <alpha_stall>1.396</alpha_stall>
        <a0>0</a0>
        <area>0.27637</area>
        <upward>0 0.707106781186547 -0.707106781186547</upward>
        <forward>0 -0.707106781186547 -0.707106781186547</forward>
        <link_name>thruster_blade</link_name>
        <cp>-0.35 0 0</cp>
      </plugin>

      <plugin
        filename="ignition-gazebo-lift-drag-system"
        name="ignition::gazebo::systems::LiftDrag">

        <air_density>1000</air_density>
        <cla>1.2535816618911175</cla>
        <cla_stall>-1.4326647564469914</cla_stall>
        <cda>0</cda>
        <cda_stall>1.4326647564469914</cda_stall>
        <alpha_stall>1.396</alpha_stall>
        <a0>0</a0>
        <area>0.27637</area>
        <upward>0.707106781186547 0 -0.707106781186547</upward>
        <forward>0.707106781186547 0 0.707106781186547</forward>
        <link_name>thruster_blade</link_name>
        <cp>0 0.35 0</cp>
      </plugin>

      <plugin
        filename="ignition-gazebo-apply-joint-force-system"
        name="ignition::gazebo::systems::ApplyJointForce">
        <joint_name>thruster_top_front_left_joint</joint_name>
      </plugin>
    </model>
  </world>
</sdf>
